Workbook

Sheet Valuation
A1: Inventory valuation — KITCHEN — 2026-08-01
A2: Source counts: Prep count July 31 (2026-07-31) + Full Count End of Month (2026-08-01). Each item is shown at its most recent physical count. Prices are the corrected prices in the system as at 2026-08-11.
A4: Item | B4: Category | C4: Storage area | D4: Supplier | E4: Quantity basis | F4: Counted on | G4: Qty counted | H4: Count unit | I4: Qty (base) | J4: Base unit | K4: Price at count ($/base) | L4: Price now ($/base) | M4: Value at count | N4: Value at current prices | O4: Change | P4: Price now (readable) | Q4: Per | R4: Pack format
A5: Baguette | B5: BREAD | C5: FREEZER | E5: Physically counted 2026-08-01 | F5: 2026-08-01 | G5: 0 | H5: each | I5: 0 | J5: each | K5: 3.135 | L5: 3.135 | M5: =I5*K5 | N5: =I5*L5 | O5: =N5-M5 | P5: 3.135 | Q5: each | R5: 20 case → 1 each
A6: Brioche Unsliced | B6: BREAD | E6: Physically counted 2026-08-01 | F6: 2026-08-01 | G6: 18 | H6: each | I6: 18 | J6: each | K6: 10.03 | L6: 10.03 | M6: =I6*K6 | N6: =I6*L6 | O6: =N6-M6 | P6: 10.03 | Q6: each | R6: 8 cs
A7: BUN BURGER SWT POTATO JAL CHDR | B7: BREAD | D7: Sysco | E7: Physically counted 2026-08-01 | F7: 2026-08-01 | G7: 2 | H7: case | I7: 10656 | J7: g | K7: 0.011991366 | L7: 0.011991366 | M7: =I7*K7 | N7: =I7*L7 | O7: =N7-M7 | P7: 11.991366 | Q7: kg | R7: 72 case → 74 each
A8: Burger Bun Sliced | B8: BREAD | E8: Physically counted 2026-08-01 | F8: 2026-08-01 | G8: 3 | H8: case | I8: 216 | J8: each | K8: 0.81138889 | L8: 0.81138889 | M8: =I8*K8 | N8: =I8*L8 | O8: =N8-M8 | P8: 0.81138889 | Q8: each | R8: 8 case → 9 each
A9: Croissant Plain | B9: BREAD | E9: Physically counted 2026-08-01 | F9: 2026-08-01 | G9: 120 | H9: each | I9: 120 | J9: each | K9: 2.7 | L9: 2.7 | M9: =I9*K9 | N9: =I9*L9 | O9: =N9-M9 | P9: 2.7 | Q9: each | R9: 1 each → 1 each
A10: cruffins | B10: BREAD | E10: Physically counted 2026-08-01 | F10: 2026-08-01 | G10: 60 | H10: each | I10: 60 | J10: each | K10: 2.6 | L10: 2.6 | M10: =I10*K10 | N10: =I10*L10 | O10: =N10-M10 | P10: 2.6 | Q10: each | R10: 1 each → 1 each
A11: ENGLISH MUFFIN GF 4PK | B11: BREAD | D11: Snow Cap | E11: Physically counted 2026-08-01 | F11: 2026-08-01 | G11: 16.3 | H11: pack | I11: 65.2 | J11: each | K11: 1.6879167 | L11: 1.6879167 | M11: =I11*K11 | N11: =I11*L11 | O11: =N11-M11 | P11: 1.6879167 | Q11: each | R11: 6 case → 4 pack
A12: GF Brioche Bun | B12: BREAD | E12: Physically counted 2026-08-01 | F12: 2026-08-01 | G12: 14 | H12: pack | I12: 84 | J12: each | K12: 1.6879167 | L12: 1.6879167 | M12: =I12*K12 | N12: =I12*L12 | O12: =N12-M12 | P12: 1.6879167 | Q12: each | R12: 4 case → 6 pack
A13: GF ENGLISH MUFFIN | B13: BREAD | D13: Sysco | E13: Physically counted 2026-08-01 | F13: 2026-08-01 | G13: 0 | H13: pack | I13: 0 | J13: each | K13: 1.6879167 | L13: 1.6879167 | M13: =I13*K13 | N13: =I13*L13 | O13: =N13-M13 | P13: 1.6879167 | Q13: each | R13: 4 case → 6 pack
A14: GF SOFT WHITE LOAF | B14: BREAD | E14: Physically counted 2026-08-01 | F14: 2026-08-01 | G14: 12 | H14: each | I14: 5760 | J14: g | K14: 0.0140625 | L14: 0.0140625 | M14: =I14*K14 | N14: =I14*L14 | O14: =N14-M14 | P14: 14.0625 | Q14: kg | R14: 4 case → 480 each
A15: Naan Bread Round 8 in | B15: BREAD | D15: Sysco | E15: Physically counted 2026-08-01 | F15: 2026-08-01 | G15: 0 | H15: pack | I15: 0 | J15: each | K15: 0.88854167 | L15: 0.88854167 | M15: =I15*K15 | N15: =I15*L15 | O15: =N15-M15 | P15: 0.88854167 | Q15: each | R15: 6 case → 8 pack
A16: Pain au Chocolate | B16: BREAD | C16: FREEZER | E16: Physically counted 2026-08-01 | F16: 2026-08-01 | G16: 66 | H16: each | I16: 66 | J16: each | K16: 2.9 | L16: 2.9 | M16: =I16*K16 | N16: =I16*L16 | O16: =N16-M16 | P16: 2.9 | Q16: each | R16: 1 each → 1 each
A17: Pastry shell chocolate | B17: BREAD | C17: CATERING | E17: Physically counted 2026-08-01 | F17: 2026-08-01 | G17: 0 | H17: each | I17: 0 | J17: each | K17: 2.0983333 | L17: 2.0983333 | M17: =I17*K17 | N17: =I17*L17 | O17: =N17-M17 | P17: 2.0983333 | Q17: each | R17: 60 case
A18: Pita Bread | B18: BREAD | E18: Physically counted 2026-08-01 | F18: 2026-08-01 | G18: 35 | H18: pack | I18: 210 | J18: each | K18: 0.27402778 | L18: 0.27402778 | M18: =I18*K18 | N18: =I18*L18 | O18: =N18-M18 | P18: 0.27402778 | Q18: each | R18: 24 case → 6 pack
A19: Pizza Margherita RETAIL 12 x 615g WOOZA | B19: BREAD | D19: Legends Haul | E19: Physically counted 2026-08-01 | F19: 2026-08-01 | G19: 0 | H19: each | I19: 0 | J19: g | K19: 0.021680217 | L19: 0.021680217 | M19: =I19*K19 | N19: =I19*L19 | O19: =N19-M19 | P19: 21.680217 | Q19: kg | R19: 12 case → 615 each
A20: Pizza Pepperoni RETAIL 12 x 600g WOOZA | B20: BREAD | D20: Legends Haul | E20: Physically counted 2026-08-01 | F20: 2026-08-01 | G20: 0 | H20: each | I20: 0 | J20: g | K20: 0.022222222 | L20: 0.022222222 | M20: =I20*K20 | N20: =I20*L20 | O20: =N20-M20 | P20: 22.222222 | Q20: kg | R20: 12 case → 600 each
A21: PUFF PASTRY CROISSANT | B21: BREAD | E21: Physically counted 2026-08-01 | F21: 2026-08-01 | G21: 10 | H21: each | I21: 10 | J21: each | K21: 18.236 | L21: 18.236 | M21: =I21*K21 | N21: =I21*L21 | O21: =N21-M21 | P21: 18.236 | Q21: each | R21: 10 case
A22: Spring roll wrappers | B22: BREAD | C22: FREEZER | E22: Physically counted 2026-08-01 | F22: 2026-08-01 | G22: 0 | H22: kg | I22: 0 | J22: g | K22: 0.012545455 | L22: 0.012545455 | M22: =I22*K22 | N22: =I22*L22 | O22: =N22-M22 | P22: 12.545455 | Q22: kg | R22: 1 each → 11000 each
A23: Yellow corn Tortillas | B23: BREAD | D23: Sysco | E23: Physically counted 2026-08-01 | F23: 2026-08-01 | G23: 11.5 | H23: pack | I23: 690 | J23: each | K23: 0.10713889 | L23: 0.10713889 | M23: =I23*K23 | N23: =I23*L23 | O23: =N23-M23 | P23: 0.10713889 | Q23: each | R23: 12 case → 60 pack
A24: DETERGENT POT/PAN MANUAL | B24: CHM | D24: Sysco | E24: Physically counted 2026-08-01 | F24: 2026-08-01 | G24: 2 | H24: each | I24: 1814.368 | J24: g | K24: 0.073028184 | L24: 0.073028184 | M24: =I24*K24 | N24: =I24*L24 | O24: =N24-M24 | P24: 73.028184 | Q24: kg | R24: 3 case → 907.184 each
A25: Butter | B25: DAIRY | C25: FRIDGE | E25: Physically counted 2026-08-01 | F25: 2026-08-01 | G25: 4.5 | H25: case | I25: 51075 | J25: g | K25: 0.015223789 | L25: 0.015223789 | M25: =I25*K25 | N25: =I25*L25 | O25: =N25-M25 | P25: 15.223789 | Q25: kg | R25: 25 case → 454 each
A26: Buttermilk | B26: DAIRY | C26: FRIDGE | E26: Physically counted 2026-08-01 | F26: 2026-08-01 | G26: 8 | H26: each | I26: 32000 | J26: ml | K26: 0.002755625 | L26: 0.002755625 | M26: =I26*K26 | N26: =I26*L26 | O26: =N26-M26 | P26: 2.755625 | Q26: L | R26: 4 case → 4000 each
A27: Cheddar smoked | B27: DAIRY | C27: FRIDGE | D27: Sysco | E27: Physically counted 2026-08-01 | F27: 2026-08-01 | G27: 9.4 | H27: kg | I27: 9400 | J27: g | K27: 0.03423 | L27: 0.03423 | M27: =I27*K27 | N27: =I27*L27 | O27: =N27-M27 | P27: 34.23 | Q27: kg | R27: 1000 case
A28: Cheddar whiite | B28: DAIRY | C28: FRIDGE | E28: Physically counted 2026-08-01 | F28: 2026-08-01 | G28: 5 | H28: kg | I28: 5000 | J28: g | K28: 0.019105727 | L28: 0.010698238 | M28: =I28*K28 | N28: =I28*L28 | O28: =N28-M28 | P28: 10.698238 | Q28: kg | R28: 2 case → 2270 each
A29: Cream cheese | B29: DAIRY | E29: Physically counted 2026-08-01 | F29: 2026-08-01 | G29: 1.5 | H29: kg | I29: 1500 | J29: g | K29: 0.015413333 | L29: 0.015413333 | M29: =I29*K29 | N29: =I29*L29 | O29: =N29-M29 | P29: 15.413333 | Q29: kg | R29: 6 case → 1500 each
A30: Cream whipped | B30: DAIRY | C30: FRIDGE | D30: Sysco | E30: Physically counted 2026-08-01 | F30: 2026-08-01 | G30: 16 | H30: each | I30: 15136 | J30: ml | K30: 0.0073506871 | L30: 0.0072482822 | M30: =I30*K30 | N30: =I30*L30 | O30: =N30-M30 | P30: 7.2482822 | Q30: L | R30: 16 case → 946 each
A31: Feta | B31: DAIRY | C31: FRIDGE | E31: Physically counted 2026-08-01 | F31: 2026-08-01 | G31: 2 | H31: case | I31: 6000 | J31: g | K31: 0.0174 | L31: 0.0174 | M31: =I31*K31 | N31: =I31*L31 | O31: =N31-M31 | P31: 17.4 | Q31: kg | R31: 1 case → 3000 each
A32: Free Run Eggs | B32: DAIRY | D32: Sysco | E32: Physically counted 2026-08-01 | F32: 2026-08-01 | G32: 19 | H32: case | I32: 3420 | J32: each | K32: 0.43333333 | L32: 0.43333333 | M32: =I32*K32 | N32: =I32*L32 | O32: =N32-M32 | P32: 0.43333333 | Q32: each | R32: 12 case → 15 pack → 1 each
A33: Goats Cheese | B33: DAIRY | C33: FRIDGE | D33: Sysco | E33: Physically counted 2026-08-01 | F33: 2026-08-01 | G33: 1 | H33: case | I33: 2000 | J33: g | K33: 0.029815 | L33: 0.029815 | M33: =I33*K33 | N33: =I33*L33 | O33: =N33-M33 | P33: 29.815 | Q33: kg | R33: 2 case → 1000 each
A34: Grana Padano | B34: DAIRY | C34: FRIDGE | D34: Sysco | E34: Physically counted 2026-08-01 | F34: 2026-08-01 | G34: 6.4 | H34: kg | I34: 6400 | J34: g | K34: 0.0293 | L34: 0.0293 | M34: =I34*K34 | N34: =I34*L34 | O34: =N34-M34 | P34: 29.3 | Q34: kg | R34: 1000 case
A35: Greek Style Yogurt | B35: DAIRY | C35: FRIDGE | D35: Sysco | E35: Physically counted 2026-08-01 | F35: 2026-08-01 | G35: 0 | H35: each | I35: 0 | J35: g | K35: 0.007565 | L35: 0.007565 | M35: =I35*K35 | N35: =I35*L35 | O35: =N35-M35 | P35: 7.565 | Q35: kg | R35: 1 each → 4000 each
A36: Halloumi | B36: DAIRY | C36: FRIDGE | D36: Sysco | E36: Physically counted 2026-08-01 | F36: 2026-08-01 | G36: 5 | H36: case | I36: 12500 | J36: g | K36: 0.033176 | L36: 0.033176 | M36: =I36*K36 | N36: =I36*L36 | O36: =N36-M36 | P36: 33.176 | Q36: kg | R36: 10 case → 250 each
A37: Havarti cheese | B37: DAIRY | C37: CATERING | D37: Sysco | E37: Physically counted 2026-08-01 | F37: 2026-08-01 | G37: 2.8 | H37: kg | I37: 2800 | J37: g | K37: 0.02186 | L37: 0.02186 | M37: =I37*K37 | N37: =I37*L37 | O37: =N37-M37 | P37: 21.86 | Q37: kg | R37: 3250 case
A38: Heavy Cream 35% | B38: DAIRY | D38: Snow Cap | E38: Physically counted 2026-08-01 | F38: 2026-08-01 | G38: 0 | H38: case | I38: 0 | J38: ml | K38: 0.00695375 | L38: 0.00695375 | M38: =I38*K38 | N38: =I38*L38 | O38: =N38-M38 | P38: 6.95375 | Q38: L | R38: 16 case → 1000 each
A39: Liquid Egg Yolk | B39: DAIRY | C39: FRIDGE | E39: Physically counted 2026-08-01 | F39: 2026-08-01 | G39: 13 | H39: kg | I39: 13000 | J39: g | K39: 0.008605 | L39: 0.008605 | M39: =I39*K39 | N39: =I39*L39 | O39: =N39-M39 | P39: 8.605 | Q39: kg | R39: 12 cs → 1000 kg
A40: Margerine Vegan | B40: DAIRY | C40: FRIDGE | E40: Physically counted 2026-08-01 | F40: 2026-08-01 | G40: 8 | H40: kg | I40: 8000 | J40: g | K40: 0.0073575 | L40: 0.0073575 | M40: =I40*K40 | N40: =I40*L40 | O40: =N40-M40 | P40: 7.3575 | Q40: kg | R40: 1 each → 8000 each
A41: Mascarpone | B41: DAIRY | C41: FRIDGE | D41: Sysco | E41: Physically counted 2026-08-01 | F41: 2026-08-01 | G41: 0 | H41: each | I41: 0 | J41: g | K41: 0.031417544 | L41: 0.031417544 | M41: =I41*K41 | N41: =I41*L41 | O41: =N41-M41 | P41: 31.417544 | Q41: kg | R41: 6 case → 475 each
...

Sheet Summary
A1: Summary — KITCHEN — 2026-08-01
A3: By category
A4: Category | B4: Lines | C4: Value at count | D4: Value at current prices | E4: Change
A5: BREAD | B5: =COUNTIF(Valuation!$B$5:$B$417,$A5) | C5: =SUMIF(Valuation!$B$5:$B$417,$A5,Valuation!$M$5:$M$417) | D5: =SUMIF(Valuation!$B$5:$B$417,$A5,Valuation!$N$5:$N$417) | E5: =D5-C5
A6: CHM | B6: =COUNTIF(Valuation!$B$5:$B$417,$A6) | C6: =SUMIF(Valuation!$B$5:$B$417,$A6,Valuation!$M$5:$M$417) | D6: =SUMIF(Valuation!$B$5:$B$417,$A6,Valuation!$N$5:$N$417) | E6: =D6-C6
A7: DAIRY | B7: =COUNTIF(Valuation!$B$5:$B$417,$A7) | C7: =SUMIF(Valuation!$B$5:$B$417,$A7,Valuation!$M$5:$M$417) | D7: =SUMIF(Valuation!$B$5:$B$417,$A7,Valuation!$N$5:$N$417) | E7: =D7-C7
A8: DRY | B8: =COUNTIF(Valuation!$B$5:$B$417,$A8) | C8: =SUMIF(Valuation!$B$5:$B$417,$A8,Valuation!$M$5:$M$417) | D8: =SUMIF(Valuation!$B$5:$B$417,$A8,Valuation!$N$5:$N$417) | E8: =D8-C8
A9: FISH | B9: =COUNTIF(Valuation!$B$5:$B$417,$A9) | C9: =SUMIF(Valuation!$B$5:$B$417,$A9,Valuation!$M$5:$M$417) | D9: =SUMIF(Valuation!$B$5:$B$417,$A9,Valuation!$N$5:$N$417) | E9: =D9-C9
A10: FROZEN | B10: =COUNTIF(Valuation!$B$5:$B$417,$A10) | C10: =SUMIF(Valuation!$B$5:$B$417,$A10,Valuation!$M$5:$M$417) | D10: =SUMIF(Valuation!$B$5:$B$417,$A10,Valuation!$N$5:$N$417) | E10: =D10-C10
A11: MEAT | B11: =COUNTIF(Valuation!$B$5:$B$417,$A11) | C11: =SUMIF(Valuation!$B$5:$B$417,$A11,Valuation!$M$5:$M$417) | D11: =SUMIF(Valuation!$B$5:$B$417,$A11,Valuation!$N$5:$N$417) | E11: =D11-C11
A12: PREPD | B12: =COUNTIF(Valuation!$B$5:$B$417,$A12) | C12: =SUMIF(Valuation!$B$5:$B$417,$A12,Valuation!$M$5:$M$417) | D12: =SUMIF(Valuation!$B$5:$B$417,$A12,Valuation!$N$5:$N$417) | E12: =D12-C12
A13: PROD | B13: =COUNTIF(Valuation!$B$5:$B$417,$A13) | C13: =SUMIF(Valuation!$B$5:$B$417,$A13,Valuation!$M$5:$M$417) | D13: =SUMIF(Valuation!$B$5:$B$417,$A13,Valuation!$N$5:$N$417) | E13: =D13-C13
A14: TOTAL | B14: =SUM(B5:B13) | C14: =SUM(C5:C13) | D14: =SUM(D5:D13) | E14: =SUM(E5:E13)
A17: How each quantity was established
A18: Each item takes its most recent physical count across the source sessions. A line that nobody counted in either session falls back to the quantity the system expected.
A19: Quantity basis | B19: Lines | C19: Value at current prices | D19: % of total
A20: Physically counted 2026-07-31 | B20: =COUNTIF(Valuation!$E$5:$E$417,$A20) | C20: =SUMIF(Valuation!$E$5:$E$417,$A20,Valuation!$N$5:$N$417) | D20: =IF($C$23=0,0,C20/$C$23)
A21: Physically counted 2026-08-01 | B21: =COUNTIF(Valuation!$E$5:$E$417,$A21) | C21: =SUMIF(Valuation!$E$5:$E$417,$A21,Valuation!$N$5:$N$417) | D21: =IF($C$23=0,0,C21/$C$23)
A22: Skipped — expected qty at 2026-08-01 | B22: =COUNTIF(Valuation!$E$5:$E$417,$A22) | C22: =SUMIF(Valuation!$E$5:$E$417,$A22,Valuation!$N$5:$N$417) | D22: =IF($C$23=0,0,C22/$C$23)
A23: TOTAL | B23: =SUM(B20:B22) | C23: =SUM(C20:C22)

Sheet Notes
A1: Basis of preparation
A3: Scope. Revenue centre KITCHEN, which is the default revenue centre — its stock is held on the inventory record itself rather than as a per-centre allocation. 413 items.
A5: Quantities. The month-end was counted across two sessions: Prep count July 31 (2026-07-31) + Full Count End of Month (2026-08-01). Neither session on its own holds the whole position, because the items counted in one appear in the other as carried-forward lines. Each item is therefore shown at its MOST RECENT PHYSICAL count, and the Counted on column says which date that was (2026-07-31: 48 items, 2026-08-01: 365 items). 412 of 413 lines rest on a physical observation.
A7: Quantities are shown both in the unit the counter worked in (Qty counted / Count unit) and in the item's base unit, which is what the system stores and what the valuation multiplies. Base quantities are the figures the count itself recorded; pack formats have been repaired since, and re-deriving a counter's entry through a corrected pack would answer a different question than the one they answered on the night.
A9: Prices. The count froze a price against each line when it was finalized. Several of those prices were subsequently found to be wrong: when a supplier changed pack size, the new case price was divided by the item's old pack size, so the cost was wrong by the ratio between them. Those items have since been corrected. This workbook values the counted quantities at the CORRECTED prices and shows the price used at count time alongside, so the restatement of each line is visible. The difference is in the Change column and is subtotalled by category on the Summary sheet.
A11: Comparatives. Counts before 30 June 2026 are not comparable with this one. Eighteen items were priced at zero in the 1 June count and eleven more at under $0.002 per base unit, and fourteen items have changed unit basis since (for example Yellow potato from each to grams), so their quantities do not line up either. The 1 June count reported $17,670; those same counted quantities at 30 June prices come to $26,942. Any trend drawn across that date reflects the repricing, not a change in stock.
A13: Items subsequently deactivated remain in this valuation, because they were on hand at the count date.
A15: Formulas. Value columns are formulas over the quantity and price columns, so correcting a price in this workbook updates the totals. Nothing is a pasted result.
A17: Check figures. The value columns are live formulas, so Excel computes them when this file opens. They should total $24,945.95 at count prices and $24,784.62 at current prices, a change of $-161.32. If the totals differ from these figures, a price has been edited since this file was produced.
A19: Source count session ids: 9ed49415-66c9-441d-a182-17bf941562fc, 33adf80a-0660-4114-b150-d010164afc51
A20: Position as at: 2026-08-01
A21: Prices as at: 2026-08-11 06:34:18 UTC
